Doc: https://learn.microsoft.com/pt-br/dotnet/csharp/fundamentals/exceptions/creating-and-throwing-exceptions

No .NET os erros que são gerados dentro da aplicação são tratados como exceptions, uma exception é algo que não deveria acontecer , mas podemos prevenir tratando essas Exceptions.

```C#
var arr = new int[] { 1, 2, 3 };  
  
for (int i = 0; i < 10; i++)  
{  
    Console.WriteLine(arr[i]);  
}
```

Nesse exemplo será gerado o erro **System.IndexOutOfRangeException***, pois o array de inteiros possui somente três posições, e a partir do momento que acesso a quarta posição, ele gera esse erro, pois não existe aquela posição dentro do array que foi criado.

### Try/Catch
```C#
var arr = new int[] { 1, 2, 3 };  
  
try  
{  
    for (int i = 0; i < 10; i++)  
    {  
        Console.WriteLine(arr[i]);  
    }  
}  
catch (Exception e)  
{  
    Console.WriteLine("Error => " + e);  
    throw;  
}  
finally  
{  
    Console.WriteLine("Finally");  
}  
  
Console.Write("Here");
```

O bloco try/catch preveni que o nosso programa quebre, nesse caso como está sendo lançado um **throw** ele irá parar a execução do nosso programa, mas poderia ser retirado esse ***throw*** que a execução continuaria normalmente.

Podemos também especificar qual tipo de erro o catch vai capturar, exemplo: 
```C#
var arr = new int[] { 1, 2, 3 };  
  
try  
{  
    for (int i = 0; i < 10; i++)  
    {  
        Console.WriteLine(arr[i]);  
    }  
}  
catch (IndexOutOfRangeException ex)  
{  
    Console.WriteLine("Error.Message => " + ex.Message);  
    Console.WriteLine("Error.Type => " + ex.GetType());  
}
```
Nesse exemplo, o código vai cair no catch somente se o erro foi ***IndexOutOfRangeException***, caso for qualquer outro erro, irá quebrar o nosso programa, pois não tem um tratamento para erros no geral dentro desse bloco.

Outro exemplo:
```C#
namespace Execeptions  
{  
    class Program  
    {  
        private static void Main()  
        {  
            try  
            {  
                Register("");  
            }  
            catch (ArgumentNullException ex)  
            {  
                Console.WriteLine("User cannot be null or empty.");  
            }  
            catch (Exception ex)  
            {  
                Console.WriteLine(ex.Message);  
            }  
        }  
        private static void Register(string user)  
        {  
            Console.WriteLine("Register");  
              
            if (string.IsNullOrEmpty(user))  
            {  
                throw new ArgumentNullException("user");  
            }  
        }
    }
}
```
Nesse exemplo também estou capturando um erro especifico para ser tratado dentro do código do bloco try catch. É sempre importante tratar o máximo de erros possíveis de maneira específica e deixar o Exception genérico somente para casos que não temos tantas informações do erro.

### Exceções customizadas
Uma maneira de deixar as exceções ainda mais especificas e deixar cada vez melhor o tratamento de erros é criando exceções customizadas, exemplo:

```C#
public class CustomException : Exception  
{  
    public CustomException(DateTime dateTime)  
    {  
        time = dateTime;  
    }  
    public DateTime time { get; }  
}
```

Usando ela:
```C#
private static void Register(string user)  
{  
    Console.WriteLine("Register");  
      
    if (string.IsNullOrEmpty(user))  
    {  
        throw new CustomException(DateTime.Now);  
    }  
}
```

Capturando no bloco try catch:
```C#
try  
{  
    Register("");  
}  
catch (CustomException ex)  
{  
    Console.WriteLine(ex.time);  
}  

```